[2025-02-03T07:53:35.653+0000] {local_task_job_runner.py:120} INFO - ::group::Pre task execution logs
[2025-02-03T07:53:35.808+0000] {taskinstance.py:2076} INFO - Dependencies all met for dep_context=non-requeueable deps ti=<TaskInstance: dbt_bash_dag_okok.dbt_debug scheduled__2025-02-02T00:00:00+00:00 [queued]>
[2025-02-03T07:53:35.888+0000] {taskinstance.py:2076} INFO - Dependencies all met for dep_context=requeueable deps ti=<TaskInstance: dbt_bash_dag_okok.dbt_debug scheduled__2025-02-02T00:00:00+00:00 [queued]>
[2025-02-03T07:53:35.894+0000] {taskinstance.py:2306} INFO - Starting attempt 1 of 1
[2025-02-03T07:53:36.033+0000] {taskinstance.py:2330} INFO - Executing <Task(BashOperator): dbt_debug> on 2025-02-02 00:00:00+00:00
[2025-02-03T07:53:36.078+0000] {warnings.py:112} WARNING - /home/***/.local/lib/python3.12/site-packages/***/task/task_runner/standard_task_runner.py:62: DeprecationWarning: This process (pid=4603) is multi-threaded, use of fork() may lead to deadlocks in the child.
  pid = os.fork()

[2025-02-03T07:53:36.082+0000] {standard_task_runner.py:90} INFO - Running: ['***', 'tasks', 'run', 'dbt_bash_dag_okok', 'dbt_debug', 'scheduled__2025-02-02T00:00:00+00:00', '--job-id', '21', '--raw', '--subdir', 'DAGS_FOLDER/test_dbt_2.py', '--cfg-path', '/tmp/tmpe9i25ome']
[2025-02-03T07:53:36.090+0000] {standard_task_runner.py:64} INFO - Started process 4604 to run task
[2025-02-03T07:53:36.090+0000] {standard_task_runner.py:91} INFO - Job 21: Subtask dbt_debug
[2025-02-03T07:53:36.427+0000] {task_command.py:426} INFO - Running <TaskInstance: dbt_bash_dag_okok.dbt_debug scheduled__2025-02-02T00:00:00+00:00 [running]> on host fd25e6dca69b
[2025-02-03T07:53:37.149+0000] {taskinstance.py:2648} INFO - Exporting env vars: AIRFLOW_CTX_DAG_OWNER='***' AIRFLOW_CTX_DAG_ID='dbt_bash_dag_okok' AIRFLOW_CTX_TASK_ID='dbt_debug' AIRFLOW_CTX_EXECUTION_DATE='2025-02-02T00:00:00+00:00' AIRFLOW_CTX_TRY_NUMBER='1' AIRFLOW_CTX_DAG_RUN_ID='scheduled__2025-02-02T00:00:00+00:00'
[2025-02-03T07:53:37.159+0000] {taskinstance.py:430} INFO - ::endgroup::
[2025-02-03T07:53:37.375+0000] {subprocess.py:63} INFO - Tmp dir root location: /tmp
[2025-02-03T07:53:37.381+0000] {subprocess.py:75} INFO - Running command: ['/usr/bin/bash', '-c', 'dbt debug --profiles-dir /home/***/.dbt']
[2025-02-03T07:53:37.415+0000] {subprocess.py:86} INFO - Output:
[2025-02-03T07:53:54.416+0000] {subprocess.py:93} INFO - [0m07:53:54  Running with dbt=1.8.8
[2025-02-03T07:53:54.928+0000] {subprocess.py:93} INFO - [0m07:53:54  dbt version: 1.8.8
[2025-02-03T07:53:54.944+0000] {subprocess.py:93} INFO - [0m07:53:54  python version: 3.12.4
[2025-02-03T07:53:54.948+0000] {subprocess.py:93} INFO - [0m07:53:54  python path: /home/***/.local/bin/python
[2025-02-03T07:53:54.966+0000] {subprocess.py:93} INFO - [0m07:53:54  os info: Linux-5.15.167.4-microsoft-standard-WSL2-x86_64-with-glibc2.36
[2025-02-03T07:53:54.973+0000] {subprocess.py:93} INFO - [0m07:53:54  Using profiles dir at /home/***/.dbt
[2025-02-03T07:53:54.977+0000] {subprocess.py:93} INFO - [0m07:53:54  Using profiles.yml file at /home/***/.dbt/profiles.yml
[2025-02-03T07:53:54.980+0000] {subprocess.py:93} INFO - [0m07:53:54  Using dbt_project.yml file at /tmp/***tmp4qlggxq_/dbt_project.yml
[2025-02-03T07:53:54.984+0000] {subprocess.py:93} INFO - [0m07:53:54  Configuration:
[2025-02-03T07:53:54.990+0000] {subprocess.py:93} INFO - [0m07:53:54    profiles.yml file [[31mERROR not found[0m]
[2025-02-03T07:53:54.996+0000] {subprocess.py:93} INFO - [0m07:53:54    dbt_project.yml file [[31mERROR not found[0m]
[2025-02-03T07:53:54.999+0000] {subprocess.py:93} INFO - [0m07:53:54  Required dependencies:
[2025-02-03T07:53:55.034+0000] {subprocess.py:93} INFO - [0m07:53:55   - git [[32mOK found[0m]
[2025-02-03T07:53:55.041+0000] {subprocess.py:93} INFO - 
[2025-02-03T07:53:55.050+0000] {subprocess.py:93} INFO - [0m07:53:55  Connection test skipped since no profile was found
[2025-02-03T07:53:55.059+0000] {subprocess.py:93} INFO - [0m07:53:55  [31m2 checks failed:[0m
[2025-02-03T07:53:55.062+0000] {subprocess.py:93} INFO - [0m07:53:55  dbt looked for a profiles.yml file in /home/***/.dbt/profiles.yml, but did
[2025-02-03T07:53:55.064+0000] {subprocess.py:93} INFO - not find one. For more information on configuring your profile, consult the
[2025-02-03T07:53:55.066+0000] {subprocess.py:93} INFO - documentation:
[2025-02-03T07:53:55.068+0000] {subprocess.py:93} INFO - 
[2025-02-03T07:53:55.072+0000] {subprocess.py:93} INFO - https://docs.getdbt.com/docs/configure-your-profile
[2025-02-03T07:53:55.075+0000] {subprocess.py:93} INFO - 
[2025-02-03T07:53:55.091+0000] {subprocess.py:93} INFO - 
[2025-02-03T07:53:55.094+0000] {subprocess.py:93} INFO - [0m07:53:55  Project loading failed for the following reason:
[2025-02-03T07:53:55.099+0000] {subprocess.py:93} INFO -  project path </tmp/***tmp4qlggxq_/dbt_project.yml> not found
[2025-02-03T07:53:55.102+0000] {subprocess.py:93} INFO - 
[2025-02-03T07:53:58.556+0000] {subprocess.py:97} INFO - Command exited with return code 1
[2025-02-03T07:53:58.571+0000] {taskinstance.py:441} INFO - ::group::Post task execution logs
[2025-02-03T07:53:58.698+0000] {taskinstance.py:2905} ERROR - Task failed with exception
Traceback (most recent call last):
  File "/home/airflow/.local/lib/python3.12/site-packages/airflow/models/taskinstance.py", line 465, in _execute_task
    result = _execute_callable(context=context, **execute_callable_kwargs)
             ^^^^^^^^^^^^^^^^^^^^^^^^^^^^^^^^^^^^^^^^^^^^^^^^^^^^^^^^^^^^^
  File "/home/airflow/.local/lib/python3.12/site-packages/airflow/models/taskinstance.py", line 432, in _execute_callable
    return execute_callable(context=context, **execute_callable_kwargs)
           ^^^^^^^^^^^^^^^^^^^^^^^^^^^^^^^^^^^^^^^^^^^^^^^^^^^^^^^^^^^^
  File "/home/airflow/.local/lib/python3.12/site-packages/airflow/models/baseoperator.py", line 401, in wrapper
    return func(self, *args, **kwargs)
           ^^^^^^^^^^^^^^^^^^^^^^^^^^^
  File "/home/airflow/.local/lib/python3.12/site-packages/airflow/operators/bash.py", line 243, in execute
    raise AirflowException(
airflow.exceptions.AirflowException: Bash command failed. The command returned a non-zero exit code 1.
[2025-02-03T07:53:58.787+0000] {taskinstance.py:1206} INFO - Marking task as FAILED. dag_id=dbt_bash_dag_okok, task_id=dbt_debug, run_id=scheduled__2025-02-02T00:00:00+00:00, execution_date=20250202T000000, start_date=20250203T075335, end_date=20250203T075358
[2025-02-03T07:53:59.021+0000] {standard_task_runner.py:110} ERROR - Failed to execute job 21 for task dbt_debug (Bash command failed. The command returned a non-zero exit code 1.; 4604)
[2025-02-03T07:53:59.182+0000] {local_task_job_runner.py:243} INFO - Task exited with return code 1
[2025-02-03T07:53:59.728+0000] {taskinstance.py:3503} INFO - 0 downstream tasks scheduled from follow-on schedule check
[2025-02-03T07:53:59.778+0000] {local_task_job_runner.py:222} INFO - ::endgroup::
