[2025-02-03T08:15:07.392+0000] {local_task_job_runner.py:120} INFO - ::group::Pre task execution logs
[2025-02-03T08:15:07.549+0000] {taskinstance.py:2076} INFO - Dependencies all met for dep_context=non-requeueable deps ti=<TaskInstance: dbt_bash_dag_okok.dbt_debug manual__2025-02-03T08:15:02.191427+00:00 [queued]>
[2025-02-03T08:15:07.604+0000] {taskinstance.py:2076} INFO - Dependencies all met for dep_context=requeueable deps ti=<TaskInstance: dbt_bash_dag_okok.dbt_debug manual__2025-02-03T08:15:02.191427+00:00 [queued]>
[2025-02-03T08:15:07.607+0000] {taskinstance.py:2306} INFO - Starting attempt 1 of 1
[2025-02-03T08:15:07.701+0000] {taskinstance.py:2330} INFO - Executing <Task(BashOperator): dbt_debug> on 2025-02-03 08:15:02.191427+00:00
[2025-02-03T08:15:07.726+0000] {warnings.py:112} WARNING - /home/***/.local/lib/python3.12/site-packages/***/task/task_runner/standard_task_runner.py:62: DeprecationWarning: This process (pid=5091) is multi-threaded, use of fork() may lead to deadlocks in the child.
  pid = os.fork()

[2025-02-03T08:15:07.732+0000] {standard_task_runner.py:64} INFO - Started process 5092 to run task
[2025-02-03T08:15:07.730+0000] {standard_task_runner.py:90} INFO - Running: ['***', 'tasks', 'run', 'dbt_bash_dag_okok', 'dbt_debug', 'manual__2025-02-03T08:15:02.191427+00:00', '--job-id', '22', '--raw', '--subdir', 'DAGS_FOLDER/test_dbt_2.py', '--cfg-path', '/tmp/tmp93oywh2n']
[2025-02-03T08:15:07.734+0000] {standard_task_runner.py:91} INFO - Job 22: Subtask dbt_debug
[2025-02-03T08:15:07.906+0000] {task_command.py:426} INFO - Running <TaskInstance: dbt_bash_dag_okok.dbt_debug manual__2025-02-03T08:15:02.191427+00:00 [running]> on host fd25e6dca69b
[2025-02-03T08:15:08.254+0000] {taskinstance.py:2648} INFO - Exporting env vars: AIRFLOW_CTX_DAG_OWNER='***' AIRFLOW_CTX_DAG_ID='dbt_bash_dag_okok' AIRFLOW_CTX_TASK_ID='dbt_debug' AIRFLOW_CTX_EXECUTION_DATE='2025-02-03T08:15:02.191427+00:00' AIRFLOW_CTX_TRY_NUMBER='1' AIRFLOW_CTX_DAG_RUN_ID='manual__2025-02-03T08:15:02.191427+00:00'
[2025-02-03T08:15:08.263+0000] {taskinstance.py:430} INFO - ::endgroup::
[2025-02-03T08:15:08.333+0000] {subprocess.py:63} INFO - Tmp dir root location: /tmp
[2025-02-03T08:15:08.347+0000] {subprocess.py:75} INFO - Running command: ['/usr/bin/bash', '-c', 'dbt debug --profiles-dir /opt/***/dbt_projects/project_1']
[2025-02-03T08:15:08.411+0000] {subprocess.py:86} INFO - Output:
[2025-02-03T08:15:23.034+0000] {subprocess.py:93} INFO - [0m08:15:23  Running with dbt=1.8.8
[2025-02-03T08:15:23.088+0000] {subprocess.py:93} INFO - [0m08:15:23  dbt version: 1.8.8
[2025-02-03T08:15:23.091+0000] {subprocess.py:93} INFO - [0m08:15:23  python version: 3.12.4
[2025-02-03T08:15:23.098+0000] {subprocess.py:93} INFO - [0m08:15:23  python path: /home/***/.local/bin/python
[2025-02-03T08:15:23.102+0000] {subprocess.py:93} INFO - [0m08:15:23  os info: Linux-5.15.167.4-microsoft-standard-WSL2-x86_64-with-glibc2.36
[2025-02-03T08:15:40.461+0000] {subprocess.py:93} INFO - [0m08:15:40  Using profiles dir at /opt/***/dbt_projects/project_1
[2025-02-03T08:15:40.465+0000] {subprocess.py:93} INFO - [0m08:15:40  Using profiles.yml file at /opt/***/dbt_projects/project_1/profiles.yml
[2025-02-03T08:15:40.471+0000] {subprocess.py:93} INFO - [0m08:15:40  Using dbt_project.yml file at /tmp/***tmp3q4bs6yy/dbt_project.yml
[2025-02-03T08:15:40.475+0000] {subprocess.py:93} INFO - [0m08:15:40  adapter type: snowflake
[2025-02-03T08:15:40.478+0000] {subprocess.py:93} INFO - [0m08:15:40  adapter version: 1.8.4
[2025-02-03T08:15:40.482+0000] {subprocess.py:93} INFO - [0m08:15:40  Configuration:
[2025-02-03T08:15:40.490+0000] {subprocess.py:93} INFO - [0m08:15:40    profiles.yml file [[32mOK found and valid[0m]
[2025-02-03T08:15:40.493+0000] {subprocess.py:93} INFO - [0m08:15:40    dbt_project.yml file [[31mERROR not found[0m]
[2025-02-03T08:15:40.496+0000] {subprocess.py:93} INFO - [0m08:15:40  Required dependencies:
[2025-02-03T08:15:40.537+0000] {subprocess.py:93} INFO - [0m08:15:40   - git [[32mOK found[0m]
[2025-02-03T08:15:40.540+0000] {subprocess.py:93} INFO - 
[2025-02-03T08:15:40.542+0000] {subprocess.py:93} INFO - [0m08:15:40  Connection:
[2025-02-03T08:15:40.545+0000] {subprocess.py:93} INFO - [0m08:15:40    account: nmbqhvk-ns46391
[2025-02-03T08:15:40.549+0000] {subprocess.py:93} INFO - [0m08:15:40    user: TUAN_123
[2025-02-03T08:15:40.555+0000] {subprocess.py:93} INFO - [0m08:15:40    database: DBT_TEST
[2025-02-03T08:15:40.559+0000] {subprocess.py:93} INFO - [0m08:15:40    warehouse: MY_WAREHOUSE
[2025-02-03T08:15:40.562+0000] {subprocess.py:93} INFO - [0m08:15:40    role: MY_ROLE
[2025-02-03T08:15:40.566+0000] {subprocess.py:93} INFO - [0m08:15:40    schema: MAIN
[2025-02-03T08:15:40.572+0000] {subprocess.py:93} INFO - [0m08:15:40    authenticator: None
[2025-02-03T08:15:40.576+0000] {subprocess.py:93} INFO - [0m08:15:40    oauth_client_id: None
[2025-02-03T08:15:40.579+0000] {subprocess.py:93} INFO - [0m08:15:40    query_tag: None
[2025-02-03T08:15:40.582+0000] {subprocess.py:93} INFO - [0m08:15:40    client_session_keep_alive: False
[2025-02-03T08:15:40.587+0000] {subprocess.py:93} INFO - [0m08:15:40    host: None
[2025-02-03T08:15:40.591+0000] {subprocess.py:93} INFO - [0m08:15:40    port: None
[2025-02-03T08:15:40.594+0000] {subprocess.py:93} INFO - [0m08:15:40    proxy_host: None
[2025-02-03T08:15:40.597+0000] {subprocess.py:93} INFO - [0m08:15:40    proxy_port: None
[2025-02-03T08:15:40.600+0000] {subprocess.py:93} INFO - [0m08:15:40    protocol: None
[2025-02-03T08:15:40.604+0000] {subprocess.py:93} INFO - [0m08:15:40    connect_retries: 1
[2025-02-03T08:15:40.607+0000] {subprocess.py:93} INFO - [0m08:15:40    connect_timeout: None
[2025-02-03T08:15:40.610+0000] {subprocess.py:93} INFO - [0m08:15:40    retry_on_database_errors: False
[2025-02-03T08:15:40.613+0000] {subprocess.py:93} INFO - [0m08:15:40    retry_all: False
[2025-02-03T08:15:40.616+0000] {subprocess.py:93} INFO - [0m08:15:40    insecure_mode: False
[2025-02-03T08:15:40.620+0000] {subprocess.py:93} INFO - [0m08:15:40    reuse_connections: None
[2025-02-03T08:15:40.624+0000] {subprocess.py:93} INFO - [0m08:15:40  Registered adapter: snowflake=1.8.4
[2025-02-03T08:15:48.317+0000] {subprocess.py:93} INFO - [0m08:15:48    Connection test: [[32mOK connection ok[0m]
[2025-02-03T08:15:48.319+0000] {subprocess.py:93} INFO - 
[2025-02-03T08:15:48.320+0000] {subprocess.py:93} INFO - [0m08:15:48  [31m1 check failed:[0m
[2025-02-03T08:15:48.322+0000] {subprocess.py:93} INFO - [0m08:15:48  Project loading failed for the following reason:
[2025-02-03T08:15:48.324+0000] {subprocess.py:93} INFO -  project path </tmp/***tmp3q4bs6yy/dbt_project.yml> not found
[2025-02-03T08:15:48.326+0000] {subprocess.py:93} INFO - 
[2025-02-03T08:15:51.469+0000] {subprocess.py:97} INFO - Command exited with return code 1
[2025-02-03T08:15:51.474+0000] {taskinstance.py:441} INFO - ::group::Post task execution logs
[2025-02-03T08:15:51.531+0000] {taskinstance.py:2905} ERROR - Task failed with exception
Traceback (most recent call last):
  File "/home/airflow/.local/lib/python3.12/site-packages/airflow/models/taskinstance.py", line 465, in _execute_task
    result = _execute_callable(context=context, **execute_callable_kwargs)
             ^^^^^^^^^^^^^^^^^^^^^^^^^^^^^^^^^^^^^^^^^^^^^^^^^^^^^^^^^^^^^
  File "/home/airflow/.local/lib/python3.12/site-packages/airflow/models/taskinstance.py", line 432, in _execute_callable
    return execute_callable(context=context, **execute_callable_kwargs)
           ^^^^^^^^^^^^^^^^^^^^^^^^^^^^^^^^^^^^^^^^^^^^^^^^^^^^^^^^^^^^
  File "/home/airflow/.local/lib/python3.12/site-packages/airflow/models/baseoperator.py", line 401, in wrapper
    return func(self, *args, **kwargs)
           ^^^^^^^^^^^^^^^^^^^^^^^^^^^
  File "/home/airflow/.local/lib/python3.12/site-packages/airflow/operators/bash.py", line 243, in execute
    raise AirflowException(
airflow.exceptions.AirflowException: Bash command failed. The command returned a non-zero exit code 1.
[2025-02-03T08:15:51.561+0000] {taskinstance.py:1206} INFO - Marking task as FAILED. dag_id=dbt_bash_dag_okok, task_id=dbt_debug, run_id=manual__2025-02-03T08:15:02.191427+00:00, execution_date=20250203T081502, start_date=20250203T081507, end_date=20250203T081551
[2025-02-03T08:15:51.641+0000] {standard_task_runner.py:110} ERROR - Failed to execute job 22 for task dbt_debug (Bash command failed. The command returned a non-zero exit code 1.; 5092)
[2025-02-03T08:15:51.691+0000] {local_task_job_runner.py:243} INFO - Task exited with return code 1
[2025-02-03T08:15:51.888+0000] {taskinstance.py:3503} INFO - 0 downstream tasks scheduled from follow-on schedule check
[2025-02-03T08:15:51.908+0000] {local_task_job_runner.py:222} INFO - ::endgroup::
