[2025-02-05T06:45:53.839+0000] {local_task_job_runner.py:120} INFO - ::group::Pre task execution logs
[2025-02-05T06:45:53.962+0000] {taskinstance.py:2076} INFO - Dependencies all met for dep_context=non-requeueable deps ti=<TaskInstance: dbt_bash_dag_okok.dbt_debug scheduled__2025-02-04T00:00:00+00:00 [queued]>
[2025-02-05T06:45:54.007+0000] {taskinstance.py:2076} INFO - Dependencies all met for dep_context=requeueable deps ti=<TaskInstance: dbt_bash_dag_okok.dbt_debug scheduled__2025-02-04T00:00:00+00:00 [queued]>
[2025-02-05T06:45:54.010+0000] {taskinstance.py:2306} INFO - Starting attempt 1 of 1
[2025-02-05T06:45:54.090+0000] {taskinstance.py:2330} INFO - Executing <Task(BashOperator): dbt_debug> on 2025-02-04 00:00:00+00:00
[2025-02-05T06:45:54.156+0000] {warnings.py:112} WARNING - /home/***/.local/lib/python3.12/site-packages/***/task/task_runner/standard_task_runner.py:62: DeprecationWarning: This process (pid=169) is multi-threaded, use of fork() may lead to deadlocks in the child.
  pid = os.fork()

[2025-02-05T06:45:54.167+0000] {standard_task_runner.py:64} INFO - Started process 171 to run task
[2025-02-05T06:45:54.179+0000] {standard_task_runner.py:90} INFO - Running: ['***', 'tasks', 'run', 'dbt_bash_dag_okok', 'dbt_debug', 'scheduled__2025-02-04T00:00:00+00:00', '--job-id', '36', '--raw', '--subdir', 'DAGS_FOLDER/test_dbt_2.py', '--cfg-path', '/tmp/tmp8ni7ge4s']
[2025-02-05T06:45:54.188+0000] {standard_task_runner.py:91} INFO - Job 36: Subtask dbt_debug
[2025-02-05T06:45:54.558+0000] {task_command.py:426} INFO - Running <TaskInstance: dbt_bash_dag_okok.dbt_debug scheduled__2025-02-04T00:00:00+00:00 [running]> on host d638101edf0d
[2025-02-05T06:45:55.001+0000] {taskinstance.py:2648} INFO - Exporting env vars: AIRFLOW_CTX_DAG_OWNER='***' AIRFLOW_CTX_DAG_ID='dbt_bash_dag_okok' AIRFLOW_CTX_TASK_ID='dbt_debug' AIRFLOW_CTX_EXECUTION_DATE='2025-02-04T00:00:00+00:00' AIRFLOW_CTX_TRY_NUMBER='1' AIRFLOW_CTX_DAG_RUN_ID='scheduled__2025-02-04T00:00:00+00:00'
[2025-02-05T06:45:55.017+0000] {taskinstance.py:430} INFO - ::endgroup::
[2025-02-05T06:45:55.237+0000] {subprocess.py:63} INFO - Tmp dir root location: /tmp
[2025-02-05T06:45:55.241+0000] {subprocess.py:75} INFO - Running command: ['/usr/bin/bash', '-c', 'dbt debug --profiles-dir /opt/***/dbt_projects/project_1']
[2025-02-05T06:45:55.286+0000] {subprocess.py:86} INFO - Output:
[2025-02-05T06:46:14.312+0000] {subprocess.py:93} INFO - [0m06:46:14  Running with dbt=1.8.8
[2025-02-05T06:46:14.723+0000] {subprocess.py:93} INFO - [0m06:46:14  dbt version: 1.8.8
[2025-02-05T06:46:14.729+0000] {subprocess.py:93} INFO - [0m06:46:14  python version: 3.12.4
[2025-02-05T06:46:14.735+0000] {subprocess.py:93} INFO - [0m06:46:14  python path: /home/***/.local/bin/python
[2025-02-05T06:46:14.739+0000] {subprocess.py:93} INFO - [0m06:46:14  os info: Linux-5.15.167.4-microsoft-standard-WSL2-x86_64-with-glibc2.36
[2025-02-05T06:46:36.916+0000] {subprocess.py:93} INFO - [0m06:46:36  Using profiles dir at /opt/***/dbt_projects/project_1
[2025-02-05T06:46:36.925+0000] {subprocess.py:93} INFO - [0m06:46:36  Using profiles.yml file at /opt/***/dbt_projects/project_1/profiles.yml
[2025-02-05T06:46:36.932+0000] {subprocess.py:93} INFO - [0m06:46:36  Using dbt_project.yml file at /tmp/***tmpuprktbby/dbt_project.yml
[2025-02-05T06:46:36.942+0000] {subprocess.py:93} INFO - [0m06:46:36  adapter type: snowflake
[2025-02-05T06:46:36.945+0000] {subprocess.py:93} INFO - [0m06:46:36  adapter version: 1.8.4
[2025-02-05T06:46:36.955+0000] {subprocess.py:93} INFO - [0m06:46:36  Configuration:
[2025-02-05T06:46:36.958+0000] {subprocess.py:93} INFO - [0m06:46:36    profiles.yml file [[32mOK found and valid[0m]
[2025-02-05T06:46:36.960+0000] {subprocess.py:93} INFO - [0m06:46:36    dbt_project.yml file [[31mERROR not found[0m]
[2025-02-05T06:46:36.962+0000] {subprocess.py:93} INFO - [0m06:46:36  Required dependencies:
[2025-02-05T06:46:37.034+0000] {subprocess.py:93} INFO - [0m06:46:37   - git [[32mOK found[0m]
[2025-02-05T06:46:37.037+0000] {subprocess.py:93} INFO - 
[2025-02-05T06:46:37.041+0000] {subprocess.py:93} INFO - [0m06:46:37  Connection:
[2025-02-05T06:46:37.046+0000] {subprocess.py:93} INFO - [0m06:46:37    account: nmbqhvk-ns46391
[2025-02-05T06:46:37.050+0000] {subprocess.py:93} INFO - [0m06:46:37    user: TUAN_123
[2025-02-05T06:46:37.056+0000] {subprocess.py:93} INFO - [0m06:46:37    database: DBT_TEST
[2025-02-05T06:46:37.058+0000] {subprocess.py:93} INFO - [0m06:46:37    warehouse: MY_WAREHOUSE
[2025-02-05T06:46:37.066+0000] {subprocess.py:93} INFO - [0m06:46:37    role: MY_ROLE
[2025-02-05T06:46:37.070+0000] {subprocess.py:93} INFO - [0m06:46:37    schema: MAIN
[2025-02-05T06:46:37.073+0000] {subprocess.py:93} INFO - [0m06:46:37    authenticator: None
[2025-02-05T06:46:37.077+0000] {subprocess.py:93} INFO - [0m06:46:37    oauth_client_id: None
[2025-02-05T06:46:37.080+0000] {subprocess.py:93} INFO - [0m06:46:37    query_tag: None
[2025-02-05T06:46:37.085+0000] {subprocess.py:93} INFO - [0m06:46:37    client_session_keep_alive: False
[2025-02-05T06:46:37.090+0000] {subprocess.py:93} INFO - [0m06:46:37    host: None
[2025-02-05T06:46:37.093+0000] {subprocess.py:93} INFO - [0m06:46:37    port: None
[2025-02-05T06:46:37.096+0000] {subprocess.py:93} INFO - [0m06:46:37    proxy_host: None
[2025-02-05T06:46:37.100+0000] {subprocess.py:93} INFO - [0m06:46:37    proxy_port: None
[2025-02-05T06:46:37.105+0000] {subprocess.py:93} INFO - [0m06:46:37    protocol: None
[2025-02-05T06:46:37.109+0000] {subprocess.py:93} INFO - [0m06:46:37    connect_retries: 1
[2025-02-05T06:46:37.114+0000] {subprocess.py:93} INFO - [0m06:46:37    connect_timeout: None
[2025-02-05T06:46:37.116+0000] {subprocess.py:93} INFO - [0m06:46:37    retry_on_database_errors: False
[2025-02-05T06:46:37.120+0000] {subprocess.py:93} INFO - [0m06:46:37    retry_all: False
[2025-02-05T06:46:37.125+0000] {subprocess.py:93} INFO - [0m06:46:37    insecure_mode: False
[2025-02-05T06:46:37.137+0000] {subprocess.py:93} INFO - [0m06:46:37    reuse_connections: None
[2025-02-05T06:46:37.144+0000] {subprocess.py:93} INFO - [0m06:46:37  Registered adapter: snowflake=1.8.4
[2025-02-05T06:46:43.757+0000] {subprocess.py:93} INFO - [0m06:46:43    Connection test: [[32mOK connection ok[0m]
[2025-02-05T06:46:43.761+0000] {subprocess.py:93} INFO - 
[2025-02-05T06:46:43.765+0000] {subprocess.py:93} INFO - [0m06:46:43  [31m1 check failed:[0m
[2025-02-05T06:46:43.769+0000] {subprocess.py:93} INFO - [0m06:46:43  Project loading failed for the following reason:
[2025-02-05T06:46:43.771+0000] {subprocess.py:93} INFO -  project path </tmp/***tmpuprktbby/dbt_project.yml> not found
[2025-02-05T06:46:43.775+0000] {subprocess.py:93} INFO - 
[2025-02-05T06:46:47.537+0000] {subprocess.py:97} INFO - Command exited with return code 1
[2025-02-05T06:46:47.542+0000] {taskinstance.py:441} INFO - ::group::Post task execution logs
[2025-02-05T06:46:47.636+0000] {taskinstance.py:2905} ERROR - Task failed with exception
Traceback (most recent call last):
  File "/home/airflow/.local/lib/python3.12/site-packages/airflow/models/taskinstance.py", line 465, in _execute_task
    result = _execute_callable(context=context, **execute_callable_kwargs)
             ^^^^^^^^^^^^^^^^^^^^^^^^^^^^^^^^^^^^^^^^^^^^^^^^^^^^^^^^^^^^^
  File "/home/airflow/.local/lib/python3.12/site-packages/airflow/models/taskinstance.py", line 432, in _execute_callable
    return execute_callable(context=context, **execute_callable_kwargs)
           ^^^^^^^^^^^^^^^^^^^^^^^^^^^^^^^^^^^^^^^^^^^^^^^^^^^^^^^^^^^^
  File "/home/airflow/.local/lib/python3.12/site-packages/airflow/models/baseoperator.py", line 401, in wrapper
    return func(self, *args, **kwargs)
           ^^^^^^^^^^^^^^^^^^^^^^^^^^^
  File "/home/airflow/.local/lib/python3.12/site-packages/airflow/operators/bash.py", line 243, in execute
    raise AirflowException(
airflow.exceptions.AirflowException: Bash command failed. The command returned a non-zero exit code 1.
[2025-02-05T06:46:47.687+0000] {taskinstance.py:1206} INFO - Marking task as FAILED. dag_id=dbt_bash_dag_okok, task_id=dbt_debug, run_id=scheduled__2025-02-04T00:00:00+00:00, execution_date=20250204T000000, start_date=20250205T064553, end_date=20250205T064647
[2025-02-05T06:46:47.822+0000] {standard_task_runner.py:110} ERROR - Failed to execute job 36 for task dbt_debug (Bash command failed. The command returned a non-zero exit code 1.; 171)
[2025-02-05T06:46:48.007+0000] {local_task_job_runner.py:243} INFO - Task exited with return code 1
[2025-02-05T06:46:48.164+0000] {local_task_job_runner.py:222} INFO - ::endgroup::
