[2025-02-05T06:45:53.839+0000] {local_task_job_runner.py:120} INFO - ::group::Pre task execution logs
[2025-02-05T06:45:53.944+0000] {taskinstance.py:2076} INFO - Dependencies all met for dep_context=non-requeueable deps ti=<TaskInstance: dbt_bash_dag_okok.dbt_debug scheduled__2025-02-03T00:00:00+00:00 [queued]>
[2025-02-05T06:45:53.992+0000] {taskinstance.py:2076} INFO - Dependencies all met for dep_context=requeueable deps ti=<TaskInstance: dbt_bash_dag_okok.dbt_debug scheduled__2025-02-03T00:00:00+00:00 [queued]>
[2025-02-05T06:45:53.995+0000] {taskinstance.py:2306} INFO - Starting attempt 1 of 1
[2025-02-05T06:45:54.069+0000] {taskinstance.py:2330} INFO - Executing <Task(BashOperator): dbt_debug> on 2025-02-03 00:00:00+00:00
[2025-02-05T06:45:54.103+0000] {warnings.py:112} WARNING - /home/***/.local/lib/python3.12/site-packages/***/task/task_runner/standard_task_runner.py:62: DeprecationWarning: This process (pid=168) is multi-threaded, use of fork() may lead to deadlocks in the child.
  pid = os.fork()

[2025-02-05T06:45:54.112+0000] {standard_task_runner.py:64} INFO - Started process 170 to run task
[2025-02-05T06:45:54.178+0000] {standard_task_runner.py:90} INFO - Running: ['***', 'tasks', 'run', 'dbt_bash_dag_okok', 'dbt_debug', 'scheduled__2025-02-03T00:00:00+00:00', '--job-id', '37', '--raw', '--subdir', 'DAGS_FOLDER/test_dbt_2.py', '--cfg-path', '/tmp/tmp4tapl4s4']
[2025-02-05T06:45:54.204+0000] {standard_task_runner.py:91} INFO - Job 37: Subtask dbt_debug
[2025-02-05T06:45:54.564+0000] {task_command.py:426} INFO - Running <TaskInstance: dbt_bash_dag_okok.dbt_debug scheduled__2025-02-03T00:00:00+00:00 [running]> on host d638101edf0d
[2025-02-05T06:45:54.989+0000] {taskinstance.py:2648} INFO - Exporting env vars: AIRFLOW_CTX_DAG_OWNER='***' AIRFLOW_CTX_DAG_ID='dbt_bash_dag_okok' AIRFLOW_CTX_TASK_ID='dbt_debug' AIRFLOW_CTX_EXECUTION_DATE='2025-02-03T00:00:00+00:00' AIRFLOW_CTX_TRY_NUMBER='1' AIRFLOW_CTX_DAG_RUN_ID='scheduled__2025-02-03T00:00:00+00:00'
[2025-02-05T06:45:55.005+0000] {taskinstance.py:430} INFO - ::endgroup::
[2025-02-05T06:45:55.235+0000] {subprocess.py:63} INFO - Tmp dir root location: /tmp
[2025-02-05T06:45:55.239+0000] {subprocess.py:75} INFO - Running command: ['/usr/bin/bash', '-c', 'dbt debug --profiles-dir /opt/***/dbt_projects/project_1']
[2025-02-05T06:45:55.280+0000] {subprocess.py:86} INFO - Output:
[2025-02-05T06:46:14.304+0000] {subprocess.py:93} INFO - [0m06:46:14  Running with dbt=1.8.8
[2025-02-05T06:46:14.726+0000] {subprocess.py:93} INFO - [0m06:46:14  dbt version: 1.8.8
[2025-02-05T06:46:14.729+0000] {subprocess.py:93} INFO - [0m06:46:14  python version: 3.12.4
[2025-02-05T06:46:14.741+0000] {subprocess.py:93} INFO - [0m06:46:14  python path: /home/***/.local/bin/python
[2025-02-05T06:46:14.748+0000] {subprocess.py:93} INFO - [0m06:46:14  os info: Linux-5.15.167.4-microsoft-standard-WSL2-x86_64-with-glibc2.36
[2025-02-05T06:46:37.011+0000] {subprocess.py:93} INFO - [0m06:46:37  Using profiles dir at /opt/***/dbt_projects/project_1
[2025-02-05T06:46:37.015+0000] {subprocess.py:93} INFO - [0m06:46:37  Using profiles.yml file at /opt/***/dbt_projects/project_1/profiles.yml
[2025-02-05T06:46:37.018+0000] {subprocess.py:93} INFO - [0m06:46:37  Using dbt_project.yml file at /tmp/***tmptybsprpk/dbt_project.yml
[2025-02-05T06:46:37.029+0000] {subprocess.py:93} INFO - [0m06:46:37  adapter type: snowflake
[2025-02-05T06:46:37.033+0000] {subprocess.py:93} INFO - [0m06:46:37  adapter version: 1.8.4
[2025-02-05T06:46:37.037+0000] {subprocess.py:93} INFO - [0m06:46:37  Configuration:
[2025-02-05T06:46:37.044+0000] {subprocess.py:93} INFO - [0m06:46:37    profiles.yml file [[32mOK found and valid[0m]
[2025-02-05T06:46:37.049+0000] {subprocess.py:93} INFO - [0m06:46:37    dbt_project.yml file [[31mERROR not found[0m]
[2025-02-05T06:46:37.057+0000] {subprocess.py:93} INFO - [0m06:46:37  Required dependencies:
[2025-02-05T06:46:37.078+0000] {subprocess.py:93} INFO - [0m06:46:37   - git [[32mOK found[0m]
[2025-02-05T06:46:37.080+0000] {subprocess.py:93} INFO - 
[2025-02-05T06:46:37.083+0000] {subprocess.py:93} INFO - [0m06:46:37  Connection:
[2025-02-05T06:46:37.088+0000] {subprocess.py:93} INFO - [0m06:46:37    account: nmbqhvk-ns46391
[2025-02-05T06:46:37.092+0000] {subprocess.py:93} INFO - [0m06:46:37    user: TUAN_123
[2025-02-05T06:46:37.095+0000] {subprocess.py:93} INFO - [0m06:46:37    database: DBT_TEST
[2025-02-05T06:46:37.120+0000] {subprocess.py:93} INFO - [0m06:46:37    warehouse: MY_WAREHOUSE
[2025-02-05T06:46:37.122+0000] {subprocess.py:93} INFO - [0m06:46:37    role: MY_ROLE
[2025-02-05T06:46:37.124+0000] {subprocess.py:93} INFO - [0m06:46:37    schema: MAIN
[2025-02-05T06:46:37.128+0000] {subprocess.py:93} INFO - [0m06:46:37    authenticator: None
[2025-02-05T06:46:37.137+0000] {subprocess.py:93} INFO - [0m06:46:37    oauth_client_id: None
[2025-02-05T06:46:37.140+0000] {subprocess.py:93} INFO - [0m06:46:37    query_tag: None
[2025-02-05T06:46:37.146+0000] {subprocess.py:93} INFO - [0m06:46:37    client_session_keep_alive: False
[2025-02-05T06:46:37.150+0000] {subprocess.py:93} INFO - [0m06:46:37    host: None
[2025-02-05T06:46:37.157+0000] {subprocess.py:93} INFO - [0m06:46:37    port: None
[2025-02-05T06:46:37.164+0000] {subprocess.py:93} INFO - [0m06:46:37    proxy_host: None
[2025-02-05T06:46:37.166+0000] {subprocess.py:93} INFO - [0m06:46:37    proxy_port: None
[2025-02-05T06:46:37.177+0000] {subprocess.py:93} INFO - [0m06:46:37    protocol: None
[2025-02-05T06:46:37.187+0000] {subprocess.py:93} INFO - [0m06:46:37    connect_retries: 1
[2025-02-05T06:46:37.194+0000] {subprocess.py:93} INFO - [0m06:46:37    connect_timeout: None
[2025-02-05T06:46:37.203+0000] {subprocess.py:93} INFO - [0m06:46:37    retry_on_database_errors: False
[2025-02-05T06:46:37.213+0000] {subprocess.py:93} INFO - [0m06:46:37    retry_all: False
[2025-02-05T06:46:37.226+0000] {subprocess.py:93} INFO - [0m06:46:37    insecure_mode: False
[2025-02-05T06:46:37.233+0000] {subprocess.py:93} INFO - [0m06:46:37    reuse_connections: None
[2025-02-05T06:46:37.239+0000] {subprocess.py:93} INFO - [0m06:46:37  Registered adapter: snowflake=1.8.4
[2025-02-05T06:46:43.855+0000] {subprocess.py:93} INFO - [0m06:46:43    Connection test: [[32mOK connection ok[0m]
[2025-02-05T06:46:43.858+0000] {subprocess.py:93} INFO - 
[2025-02-05T06:46:43.861+0000] {subprocess.py:93} INFO - [0m06:46:43  [31m1 check failed:[0m
[2025-02-05T06:46:43.864+0000] {subprocess.py:93} INFO - [0m06:46:43  Project loading failed for the following reason:
[2025-02-05T06:46:43.867+0000] {subprocess.py:93} INFO -  project path </tmp/***tmptybsprpk/dbt_project.yml> not found
[2025-02-05T06:46:43.869+0000] {subprocess.py:93} INFO - 
[2025-02-05T06:46:47.521+0000] {subprocess.py:97} INFO - Command exited with return code 1
[2025-02-05T06:46:47.526+0000] {taskinstance.py:441} INFO - ::group::Post task execution logs
[2025-02-05T06:46:47.639+0000] {taskinstance.py:2905} ERROR - Task failed with exception
Traceback (most recent call last):
  File "/home/airflow/.local/lib/python3.12/site-packages/airflow/models/taskinstance.py", line 465, in _execute_task
    result = _execute_callable(context=context, **execute_callable_kwargs)
             ^^^^^^^^^^^^^^^^^^^^^^^^^^^^^^^^^^^^^^^^^^^^^^^^^^^^^^^^^^^^^
  File "/home/airflow/.local/lib/python3.12/site-packages/airflow/models/taskinstance.py", line 432, in _execute_callable
    return execute_callable(context=context, **execute_callable_kwargs)
           ^^^^^^^^^^^^^^^^^^^^^^^^^^^^^^^^^^^^^^^^^^^^^^^^^^^^^^^^^^^^
  File "/home/airflow/.local/lib/python3.12/site-packages/airflow/models/baseoperator.py", line 401, in wrapper
    return func(self, *args, **kwargs)
           ^^^^^^^^^^^^^^^^^^^^^^^^^^^
  File "/home/airflow/.local/lib/python3.12/site-packages/airflow/operators/bash.py", line 243, in execute
    raise AirflowException(
airflow.exceptions.AirflowException: Bash command failed. The command returned a non-zero exit code 1.
[2025-02-05T06:46:47.681+0000] {taskinstance.py:1206} INFO - Marking task as FAILED. dag_id=dbt_bash_dag_okok, task_id=dbt_debug, run_id=scheduled__2025-02-03T00:00:00+00:00, execution_date=20250203T000000, start_date=20250205T064553, end_date=20250205T064647
[2025-02-05T06:46:47.815+0000] {standard_task_runner.py:110} ERROR - Failed to execute job 37 for task dbt_debug (Bash command failed. The command returned a non-zero exit code 1.; 170)
[2025-02-05T06:46:47.949+0000] {local_task_job_runner.py:243} INFO - Task exited with return code 1
[2025-02-05T06:46:48.129+0000] {local_task_job_runner.py:222} INFO - ::endgroup::
