[2025-02-03T07:53:35.612+0000] {local_task_job_runner.py:120} INFO - ::group::Pre task execution logs
[2025-02-03T07:53:35.746+0000] {taskinstance.py:2076} INFO - Dependencies all met for dep_context=non-requeueable deps ti=<TaskInstance: dbt_bash_dag_okok.dbt_debug manual__2025-02-03T07:53:22.802320+00:00 [queued]>
[2025-02-03T07:53:35.806+0000] {taskinstance.py:2076} INFO - Dependencies all met for dep_context=requeueable deps ti=<TaskInstance: dbt_bash_dag_okok.dbt_debug manual__2025-02-03T07:53:22.802320+00:00 [queued]>
[2025-02-03T07:53:35.810+0000] {taskinstance.py:2306} INFO - Starting attempt 1 of 1
[2025-02-03T07:53:35.953+0000] {taskinstance.py:2330} INFO - Executing <Task(BashOperator): dbt_debug> on 2025-02-03 07:53:22.802320+00:00
[2025-02-03T07:53:35.997+0000] {warnings.py:112} WARNING - /home/***/.local/lib/python3.12/site-packages/***/task/task_runner/standard_task_runner.py:62: DeprecationWarning: This process (pid=4590) is multi-threaded, use of fork() may lead to deadlocks in the child.
  pid = os.fork()

[2025-02-03T07:53:36.012+0000] {standard_task_runner.py:64} INFO - Started process 4598 to run task
[2025-02-03T07:53:36.018+0000] {standard_task_runner.py:90} INFO - Running: ['***', 'tasks', 'run', 'dbt_bash_dag_okok', 'dbt_debug', 'manual__2025-02-03T07:53:22.802320+00:00', '--job-id', '20', '--raw', '--subdir', 'DAGS_FOLDER/test_dbt_2.py', '--cfg-path', '/tmp/tmpfa3d7j4d']
[2025-02-03T07:53:36.026+0000] {standard_task_runner.py:91} INFO - Job 20: Subtask dbt_debug
[2025-02-03T07:53:36.343+0000] {task_command.py:426} INFO - Running <TaskInstance: dbt_bash_dag_okok.dbt_debug manual__2025-02-03T07:53:22.802320+00:00 [running]> on host 808933a904f2
[2025-02-03T07:53:37.076+0000] {taskinstance.py:2648} INFO - Exporting env vars: AIRFLOW_CTX_DAG_OWNER='***' AIRFLOW_CTX_DAG_ID='dbt_bash_dag_okok' AIRFLOW_CTX_TASK_ID='dbt_debug' AIRFLOW_CTX_EXECUTION_DATE='2025-02-03T07:53:22.802320+00:00' AIRFLOW_CTX_TRY_NUMBER='1' AIRFLOW_CTX_DAG_RUN_ID='manual__2025-02-03T07:53:22.802320+00:00'
[2025-02-03T07:53:37.086+0000] {taskinstance.py:430} INFO - ::endgroup::
[2025-02-03T07:53:37.307+0000] {subprocess.py:63} INFO - Tmp dir root location: /tmp
[2025-02-03T07:53:37.313+0000] {subprocess.py:75} INFO - Running command: ['/usr/bin/bash', '-c', 'dbt debug --profiles-dir /home/***/.dbt']
[2025-02-03T07:53:37.360+0000] {subprocess.py:86} INFO - Output:
[2025-02-03T07:53:54.437+0000] {subprocess.py:93} INFO - [0m07:53:54  Running with dbt=1.8.8
[2025-02-03T07:53:54.911+0000] {subprocess.py:93} INFO - [0m07:53:54  dbt version: 1.8.8
[2025-02-03T07:53:54.915+0000] {subprocess.py:93} INFO - [0m07:53:54  python version: 3.12.4
[2025-02-03T07:53:54.927+0000] {subprocess.py:93} INFO - [0m07:53:54  python path: /home/***/.local/bin/python
[2025-02-03T07:53:54.930+0000] {subprocess.py:93} INFO - [0m07:53:54  os info: Linux-5.15.167.4-microsoft-standard-WSL2-x86_64-with-glibc2.36
[2025-02-03T07:53:54.946+0000] {subprocess.py:93} INFO - [0m07:53:54  Using profiles dir at /home/***/.dbt
[2025-02-03T07:53:54.952+0000] {subprocess.py:93} INFO - [0m07:53:54  Using profiles.yml file at /home/***/.dbt/profiles.yml
[2025-02-03T07:53:54.973+0000] {subprocess.py:93} INFO - [0m07:53:54  Using dbt_project.yml file at /tmp/***tmpy80vof20/dbt_project.yml
[2025-02-03T07:53:54.982+0000] {subprocess.py:93} INFO - [0m07:53:54  Configuration:
[2025-02-03T07:53:54.985+0000] {subprocess.py:93} INFO - [0m07:53:54    profiles.yml file [[31mERROR not found[0m]
[2025-02-03T07:53:54.988+0000] {subprocess.py:93} INFO - [0m07:53:54    dbt_project.yml file [[31mERROR not found[0m]
[2025-02-03T07:53:54.990+0000] {subprocess.py:93} INFO - [0m07:53:54  Required dependencies:
[2025-02-03T07:53:55.014+0000] {subprocess.py:93} INFO - [0m07:53:55   - git [[32mOK found[0m]
[2025-02-03T07:53:55.016+0000] {subprocess.py:93} INFO - 
[2025-02-03T07:53:55.027+0000] {subprocess.py:93} INFO - [0m07:53:55  Connection test skipped since no profile was found
[2025-02-03T07:53:55.030+0000] {subprocess.py:93} INFO - [0m07:53:55  [31m2 checks failed:[0m
[2025-02-03T07:53:55.032+0000] {subprocess.py:93} INFO - [0m07:53:55  dbt looked for a profiles.yml file in /home/***/.dbt/profiles.yml, but did
[2025-02-03T07:53:55.035+0000] {subprocess.py:93} INFO - not find one. For more information on configuring your profile, consult the
[2025-02-03T07:53:55.043+0000] {subprocess.py:93} INFO - documentation:
[2025-02-03T07:53:55.050+0000] {subprocess.py:93} INFO - 
[2025-02-03T07:53:55.058+0000] {subprocess.py:93} INFO - https://docs.getdbt.com/docs/configure-your-profile
[2025-02-03T07:53:55.065+0000] {subprocess.py:93} INFO - 
[2025-02-03T07:53:55.073+0000] {subprocess.py:93} INFO - 
[2025-02-03T07:53:55.075+0000] {subprocess.py:93} INFO - [0m07:53:55  Project loading failed for the following reason:
[2025-02-03T07:53:55.078+0000] {subprocess.py:93} INFO -  project path </tmp/***tmpy80vof20/dbt_project.yml> not found
[2025-02-03T07:53:55.080+0000] {subprocess.py:93} INFO - 
[2025-02-03T07:53:58.600+0000] {subprocess.py:97} INFO - Command exited with return code 1
[2025-02-03T07:53:58.617+0000] {taskinstance.py:441} INFO - ::group::Post task execution logs
[2025-02-03T07:53:58.724+0000] {taskinstance.py:2905} ERROR - Task failed with exception
Traceback (most recent call last):
  File "/home/airflow/.local/lib/python3.12/site-packages/airflow/models/taskinstance.py", line 465, in _execute_task
    result = _execute_callable(context=context, **execute_callable_kwargs)
             ^^^^^^^^^^^^^^^^^^^^^^^^^^^^^^^^^^^^^^^^^^^^^^^^^^^^^^^^^^^^^
  File "/home/airflow/.local/lib/python3.12/site-packages/airflow/models/taskinstance.py", line 432, in _execute_callable
    return execute_callable(context=context, **execute_callable_kwargs)
           ^^^^^^^^^^^^^^^^^^^^^^^^^^^^^^^^^^^^^^^^^^^^^^^^^^^^^^^^^^^^
  File "/home/airflow/.local/lib/python3.12/site-packages/airflow/models/baseoperator.py", line 401, in wrapper
    return func(self, *args, **kwargs)
           ^^^^^^^^^^^^^^^^^^^^^^^^^^^
  File "/home/airflow/.local/lib/python3.12/site-packages/airflow/operators/bash.py", line 243, in execute
    raise AirflowException(
airflow.exceptions.AirflowException: Bash command failed. The command returned a non-zero exit code 1.
[2025-02-03T07:53:58.777+0000] {taskinstance.py:1206} INFO - Marking task as FAILED. dag_id=dbt_bash_dag_okok, task_id=dbt_debug, run_id=manual__2025-02-03T07:53:22.802320+00:00, execution_date=20250203T075322, start_date=20250203T075335, end_date=20250203T075358
[2025-02-03T07:53:58.953+0000] {standard_task_runner.py:110} ERROR - Failed to execute job 20 for task dbt_debug (Bash command failed. The command returned a non-zero exit code 1.; 4598)
[2025-02-03T07:53:59.107+0000] {local_task_job_runner.py:243} INFO - Task exited with return code 1
[2025-02-03T07:53:59.196+0000] {local_task_job_runner.py:222} INFO - ::endgroup::
