[2025-02-03T08:16:57.679+0000] {local_task_job_runner.py:120} INFO - ::group::Pre task execution logs
[2025-02-03T08:16:57.746+0000] {taskinstance.py:2076} INFO - Dependencies all met for dep_context=non-requeueable deps ti=<TaskInstance: dbt_bash_dag_okok.dbt_debug manual__2025-02-03T08:16:54.072488+00:00 [queued]>
[2025-02-03T08:16:57.778+0000] {taskinstance.py:2076} INFO - Dependencies all met for dep_context=requeueable deps ti=<TaskInstance: dbt_bash_dag_okok.dbt_debug manual__2025-02-03T08:16:54.072488+00:00 [queued]>
[2025-02-03T08:16:57.780+0000] {taskinstance.py:2306} INFO - Starting attempt 1 of 1
[2025-02-03T08:16:57.830+0000] {taskinstance.py:2330} INFO - Executing <Task(BashOperator): dbt_debug> on 2025-02-03 08:16:54.072488+00:00
[2025-02-03T08:16:57.853+0000] {warnings.py:112} WARNING - /home/***/.local/lib/python3.12/site-packages/***/task/task_runner/standard_task_runner.py:62: DeprecationWarning: This process (pid=5121) is multi-threaded, use of fork() may lead to deadlocks in the child.
  pid = os.fork()

[2025-02-03T08:16:57.863+0000] {standard_task_runner.py:64} INFO - Started process 5129 to run task
[2025-02-03T08:16:57.869+0000] {standard_task_runner.py:90} INFO - Running: ['***', 'tasks', 'run', 'dbt_bash_dag_okok', 'dbt_debug', 'manual__2025-02-03T08:16:54.072488+00:00', '--job-id', '23', '--raw', '--subdir', 'DAGS_FOLDER/test_dbt_2.py', '--cfg-path', '/tmp/tmpptqbvmty']
[2025-02-03T08:16:57.876+0000] {standard_task_runner.py:91} INFO - Job 23: Subtask dbt_debug
[2025-02-03T08:16:58.195+0000] {task_command.py:426} INFO - Running <TaskInstance: dbt_bash_dag_okok.dbt_debug manual__2025-02-03T08:16:54.072488+00:00 [running]> on host 808933a904f2
[2025-02-03T08:16:58.739+0000] {taskinstance.py:2648} INFO - Exporting env vars: AIRFLOW_CTX_DAG_OWNER='***' AIRFLOW_CTX_DAG_ID='dbt_bash_dag_okok' AIRFLOW_CTX_TASK_ID='dbt_debug' AIRFLOW_CTX_EXECUTION_DATE='2025-02-03T08:16:54.072488+00:00' AIRFLOW_CTX_TRY_NUMBER='1' AIRFLOW_CTX_DAG_RUN_ID='manual__2025-02-03T08:16:54.072488+00:00'
[2025-02-03T08:16:58.746+0000] {taskinstance.py:430} INFO - ::endgroup::
[2025-02-03T08:16:58.836+0000] {subprocess.py:63} INFO - Tmp dir root location: /tmp
[2025-02-03T08:16:58.841+0000] {subprocess.py:75} INFO - Running command: ['/usr/bin/bash', '-c', 'dbt debug --profiles-dir /opt/***/dbt_projects/project_1']
[2025-02-03T08:16:58.894+0000] {subprocess.py:86} INFO - Output:
[2025-02-03T08:17:10.437+0000] {subprocess.py:93} INFO - [0m08:17:10  Running with dbt=1.8.8
[2025-02-03T08:17:10.485+0000] {subprocess.py:93} INFO - [0m08:17:10  dbt version: 1.8.8
[2025-02-03T08:17:10.489+0000] {subprocess.py:93} INFO - [0m08:17:10  python version: 3.12.4
[2025-02-03T08:17:10.492+0000] {subprocess.py:93} INFO - [0m08:17:10  python path: /home/***/.local/bin/python
[2025-02-03T08:17:10.494+0000] {subprocess.py:93} INFO - [0m08:17:10  os info: Linux-5.15.167.4-microsoft-standard-WSL2-x86_64-with-glibc2.36
[2025-02-03T08:17:24.126+0000] {subprocess.py:93} INFO - [0m08:17:24  Using profiles dir at /opt/***/dbt_projects/project_1
[2025-02-03T08:17:24.131+0000] {subprocess.py:93} INFO - [0m08:17:24  Using profiles.yml file at /opt/***/dbt_projects/project_1/profiles.yml
[2025-02-03T08:17:24.134+0000] {subprocess.py:93} INFO - [0m08:17:24  Using dbt_project.yml file at /tmp/***tmpq4karzr9/dbt_project.yml
[2025-02-03T08:17:24.137+0000] {subprocess.py:93} INFO - [0m08:17:24  adapter type: snowflake
[2025-02-03T08:17:24.140+0000] {subprocess.py:93} INFO - [0m08:17:24  adapter version: 1.8.4
[2025-02-03T08:17:24.146+0000] {subprocess.py:93} INFO - [0m08:17:24  Configuration:
[2025-02-03T08:17:24.149+0000] {subprocess.py:93} INFO - [0m08:17:24    profiles.yml file [[32mOK found and valid[0m]
[2025-02-03T08:17:24.151+0000] {subprocess.py:93} INFO - [0m08:17:24    dbt_project.yml file [[31mERROR not found[0m]
[2025-02-03T08:17:24.153+0000] {subprocess.py:93} INFO - [0m08:17:24  Required dependencies:
[2025-02-03T08:17:24.190+0000] {subprocess.py:93} INFO - [0m08:17:24   - git [[32mOK found[0m]
[2025-02-03T08:17:24.192+0000] {subprocess.py:93} INFO - 
[2025-02-03T08:17:24.194+0000] {subprocess.py:93} INFO - [0m08:17:24  Connection:
[2025-02-03T08:17:24.197+0000] {subprocess.py:93} INFO - [0m08:17:24    account: nmbqhvk-ns46391
[2025-02-03T08:17:24.200+0000] {subprocess.py:93} INFO - [0m08:17:24    user: TUAN_123
[2025-02-03T08:17:24.203+0000] {subprocess.py:93} INFO - [0m08:17:24    database: DBT_TEST
[2025-02-03T08:17:24.205+0000] {subprocess.py:93} INFO - [0m08:17:24    warehouse: MY_WAREHOUSE
[2025-02-03T08:17:24.208+0000] {subprocess.py:93} INFO - [0m08:17:24    role: MY_ROLE
[2025-02-03T08:17:24.212+0000] {subprocess.py:93} INFO - [0m08:17:24    schema: MAIN
[2025-02-03T08:17:24.215+0000] {subprocess.py:93} INFO - [0m08:17:24    authenticator: None
[2025-02-03T08:17:24.217+0000] {subprocess.py:93} INFO - [0m08:17:24    oauth_client_id: None
[2025-02-03T08:17:24.219+0000] {subprocess.py:93} INFO - [0m08:17:24    query_tag: None
[2025-02-03T08:17:24.221+0000] {subprocess.py:93} INFO - [0m08:17:24    client_session_keep_alive: False
[2025-02-03T08:17:24.224+0000] {subprocess.py:93} INFO - [0m08:17:24    host: None
[2025-02-03T08:17:24.227+0000] {subprocess.py:93} INFO - [0m08:17:24    port: None
[2025-02-03T08:17:24.230+0000] {subprocess.py:93} INFO - [0m08:17:24    proxy_host: None
[2025-02-03T08:17:24.233+0000] {subprocess.py:93} INFO - [0m08:17:24    proxy_port: None
[2025-02-03T08:17:24.236+0000] {subprocess.py:93} INFO - [0m08:17:24    protocol: None
[2025-02-03T08:17:24.238+0000] {subprocess.py:93} INFO - [0m08:17:24    connect_retries: 1
[2025-02-03T08:17:24.240+0000] {subprocess.py:93} INFO - [0m08:17:24    connect_timeout: None
[2025-02-03T08:17:24.242+0000] {subprocess.py:93} INFO - [0m08:17:24    retry_on_database_errors: False
[2025-02-03T08:17:24.246+0000] {subprocess.py:93} INFO - [0m08:17:24    retry_all: False
[2025-02-03T08:17:24.249+0000] {subprocess.py:93} INFO - [0m08:17:24    insecure_mode: False
[2025-02-03T08:17:24.252+0000] {subprocess.py:93} INFO - [0m08:17:24    reuse_connections: None
[2025-02-03T08:17:24.255+0000] {subprocess.py:93} INFO - [0m08:17:24  Registered adapter: snowflake=1.8.4
[2025-02-03T08:17:31.651+0000] {subprocess.py:93} INFO - [0m08:17:31    Connection test: [[32mOK connection ok[0m]
[2025-02-03T08:17:31.653+0000] {subprocess.py:93} INFO - 
[2025-02-03T08:17:31.655+0000] {subprocess.py:93} INFO - [0m08:17:31  [31m1 check failed:[0m
[2025-02-03T08:17:31.656+0000] {subprocess.py:93} INFO - [0m08:17:31  Project loading failed for the following reason:
[2025-02-03T08:17:31.658+0000] {subprocess.py:93} INFO -  project path </tmp/***tmpq4karzr9/dbt_project.yml> not found
[2025-02-03T08:17:31.660+0000] {subprocess.py:93} INFO - 
[2025-02-03T08:17:34.228+0000] {subprocess.py:97} INFO - Command exited with return code 1
[2025-02-03T08:17:34.232+0000] {taskinstance.py:441} INFO - ::group::Post task execution logs
[2025-02-03T08:17:34.255+0000] {taskinstance.py:2905} ERROR - Task failed with exception
Traceback (most recent call last):
  File "/home/airflow/.local/lib/python3.12/site-packages/airflow/models/taskinstance.py", line 465, in _execute_task
    result = _execute_callable(context=context, **execute_callable_kwargs)
             ^^^^^^^^^^^^^^^^^^^^^^^^^^^^^^^^^^^^^^^^^^^^^^^^^^^^^^^^^^^^^
  File "/home/airflow/.local/lib/python3.12/site-packages/airflow/models/taskinstance.py", line 432, in _execute_callable
    return execute_callable(context=context, **execute_callable_kwargs)
           ^^^^^^^^^^^^^^^^^^^^^^^^^^^^^^^^^^^^^^^^^^^^^^^^^^^^^^^^^^^^
  File "/home/airflow/.local/lib/python3.12/site-packages/airflow/models/baseoperator.py", line 401, in wrapper
    return func(self, *args, **kwargs)
           ^^^^^^^^^^^^^^^^^^^^^^^^^^^
  File "/home/airflow/.local/lib/python3.12/site-packages/airflow/operators/bash.py", line 243, in execute
    raise AirflowException(
airflow.exceptions.AirflowException: Bash command failed. The command returned a non-zero exit code 1.
[2025-02-03T08:17:34.268+0000] {taskinstance.py:1206} INFO - Marking task as FAILED. dag_id=dbt_bash_dag_okok, task_id=dbt_debug, run_id=manual__2025-02-03T08:16:54.072488+00:00, execution_date=20250203T081654, start_date=20250203T081657, end_date=20250203T081734
[2025-02-03T08:17:34.299+0000] {standard_task_runner.py:110} ERROR - Failed to execute job 23 for task dbt_debug (Bash command failed. The command returned a non-zero exit code 1.; 5129)
[2025-02-03T08:17:34.347+0000] {local_task_job_runner.py:243} INFO - Task exited with return code 1
[2025-02-03T08:17:34.406+0000] {taskinstance.py:3503} INFO - 0 downstream tasks scheduled from follow-on schedule check
[2025-02-03T08:17:34.416+0000] {local_task_job_runner.py:222} INFO - ::endgroup::
