[2025-02-05T07:07:59.056+0000] {local_task_job_runner.py:120} INFO - ::group::Pre task execution logs
[2025-02-05T07:07:59.154+0000] {taskinstance.py:2076} INFO - Dependencies all met for dep_context=non-requeueable deps ti=<TaskInstance: dbt_bash_dag_okok.dbt_debug manual__2025-02-05T07:07:51.829582+00:00 [queued]>
[2025-02-05T07:07:59.279+0000] {taskinstance.py:2076} INFO - Dependencies all met for dep_context=requeueable deps ti=<TaskInstance: dbt_bash_dag_okok.dbt_debug manual__2025-02-05T07:07:51.829582+00:00 [queued]>
[2025-02-05T07:07:59.327+0000] {taskinstance.py:2306} INFO - Starting attempt 1 of 1
[2025-02-05T07:07:59.501+0000] {taskinstance.py:2330} INFO - Executing <Task(BashOperator): dbt_debug> on 2025-02-05 07:07:51.829582+00:00
[2025-02-05T07:07:59.613+0000] {warnings.py:112} WARNING - /home/***/.local/lib/python3.12/site-packages/***/task/task_runner/standard_task_runner.py:62: DeprecationWarning: This process (pid=260) is multi-threaded, use of fork() may lead to deadlocks in the child.
  pid = os.fork()

[2025-02-05T07:07:59.632+0000] {standard_task_runner.py:64} INFO - Started process 268 to run task
[2025-02-05T07:07:59.641+0000] {standard_task_runner.py:90} INFO - Running: ['***', 'tasks', 'run', 'dbt_bash_dag_okok', 'dbt_debug', 'manual__2025-02-05T07:07:51.829582+00:00', '--job-id', '43', '--raw', '--subdir', 'DAGS_FOLDER/test_dbt_2.py', '--cfg-path', '/tmp/tmpcx63p42n']
[2025-02-05T07:07:59.654+0000] {standard_task_runner.py:91} INFO - Job 43: Subtask dbt_debug
[2025-02-05T07:07:59.904+0000] {task_command.py:426} INFO - Running <TaskInstance: dbt_bash_dag_okok.dbt_debug manual__2025-02-05T07:07:51.829582+00:00 [running]> on host 06ae037e0797
[2025-02-05T07:08:00.369+0000] {taskinstance.py:2648} INFO - Exporting env vars: AIRFLOW_CTX_DAG_OWNER='***' AIRFLOW_CTX_DAG_ID='dbt_bash_dag_okok' AIRFLOW_CTX_TASK_ID='dbt_debug' AIRFLOW_CTX_EXECUTION_DATE='2025-02-05T07:07:51.829582+00:00' AIRFLOW_CTX_TRY_NUMBER='1' AIRFLOW_CTX_DAG_RUN_ID='manual__2025-02-05T07:07:51.829582+00:00'
[2025-02-05T07:08:00.376+0000] {taskinstance.py:430} INFO - ::endgroup::
[2025-02-05T07:08:00.442+0000] {subprocess.py:63} INFO - Tmp dir root location: /tmp
[2025-02-05T07:08:00.447+0000] {subprocess.py:75} INFO - Running command: ['/usr/bin/bash', '-c', 'dbt debug --profiles-dir /opt/***/dbt_projects/project_1']
[2025-02-05T07:08:00.488+0000] {subprocess.py:86} INFO - Output:
[2025-02-05T07:08:15.331+0000] {subprocess.py:93} INFO - [0m07:08:15  Running with dbt=1.8.8
[2025-02-05T07:08:15.768+0000] {subprocess.py:93} INFO - [0m07:08:15  dbt version: 1.8.8
[2025-02-05T07:08:15.772+0000] {subprocess.py:93} INFO - [0m07:08:15  python version: 3.12.4
[2025-02-05T07:08:15.776+0000] {subprocess.py:93} INFO - [0m07:08:15  python path: /home/***/.local/bin/python
[2025-02-05T07:08:15.780+0000] {subprocess.py:93} INFO - [0m07:08:15  os info: Linux-5.15.167.4-microsoft-standard-WSL2-x86_64-with-glibc2.36
[2025-02-05T07:08:30.227+0000] {subprocess.py:93} INFO - [0m07:08:30  Using profiles dir at /opt/***/dbt_projects/project_1
[2025-02-05T07:08:30.229+0000] {subprocess.py:93} INFO - [0m07:08:30  Using profiles.yml file at /opt/***/dbt_projects/project_1/profiles.yml
[2025-02-05T07:08:30.232+0000] {subprocess.py:93} INFO - [0m07:08:30  Using dbt_project.yml file at /tmp/***tmpiz127kmn/dbt_project.yml
[2025-02-05T07:08:30.236+0000] {subprocess.py:93} INFO - [0m07:08:30  adapter type: snowflake
[2025-02-05T07:08:30.238+0000] {subprocess.py:93} INFO - [0m07:08:30  adapter version: 1.8.4
[2025-02-05T07:08:30.241+0000] {subprocess.py:93} INFO - [0m07:08:30  Configuration:
[2025-02-05T07:08:30.243+0000] {subprocess.py:93} INFO - [0m07:08:30    profiles.yml file [[32mOK found and valid[0m]
[2025-02-05T07:08:30.246+0000] {subprocess.py:93} INFO - [0m07:08:30    dbt_project.yml file [[31mERROR not found[0m]
[2025-02-05T07:08:30.248+0000] {subprocess.py:93} INFO - [0m07:08:30  Required dependencies:
[2025-02-05T07:08:30.286+0000] {subprocess.py:93} INFO - [0m07:08:30   - git [[32mOK found[0m]
[2025-02-05T07:08:30.287+0000] {subprocess.py:93} INFO - 
[2025-02-05T07:08:30.289+0000] {subprocess.py:93} INFO - [0m07:08:30  Connection:
[2025-02-05T07:08:30.291+0000] {subprocess.py:93} INFO - [0m07:08:30    account: nmbqhvk-ns46391
[2025-02-05T07:08:30.293+0000] {subprocess.py:93} INFO - [0m07:08:30    user: TUAN_123
[2025-02-05T07:08:30.295+0000] {subprocess.py:93} INFO - [0m07:08:30    database: DBT_TEST
[2025-02-05T07:08:30.297+0000] {subprocess.py:93} INFO - [0m07:08:30    warehouse: MY_WAREHOUSE
[2025-02-05T07:08:30.299+0000] {subprocess.py:93} INFO - [0m07:08:30    role: MY_ROLE
[2025-02-05T07:08:30.302+0000] {subprocess.py:93} INFO - [0m07:08:30    schema: MAIN
[2025-02-05T07:08:30.305+0000] {subprocess.py:93} INFO - [0m07:08:30    authenticator: None
[2025-02-05T07:08:30.309+0000] {subprocess.py:93} INFO - [0m07:08:30    oauth_client_id: None
[2025-02-05T07:08:30.311+0000] {subprocess.py:93} INFO - [0m07:08:30    query_tag: None
[2025-02-05T07:08:30.314+0000] {subprocess.py:93} INFO - [0m07:08:30    client_session_keep_alive: False
[2025-02-05T07:08:30.317+0000] {subprocess.py:93} INFO - [0m07:08:30    host: None
[2025-02-05T07:08:30.321+0000] {subprocess.py:93} INFO - [0m07:08:30    port: None
[2025-02-05T07:08:30.324+0000] {subprocess.py:93} INFO - [0m07:08:30    proxy_host: None
[2025-02-05T07:08:30.330+0000] {subprocess.py:93} INFO - [0m07:08:30    proxy_port: None
[2025-02-05T07:08:30.334+0000] {subprocess.py:93} INFO - [0m07:08:30    protocol: None
[2025-02-05T07:08:30.338+0000] {subprocess.py:93} INFO - [0m07:08:30    connect_retries: 1
[2025-02-05T07:08:30.343+0000] {subprocess.py:93} INFO - [0m07:08:30    connect_timeout: None
[2025-02-05T07:08:30.345+0000] {subprocess.py:93} INFO - [0m07:08:30    retry_on_database_errors: False
[2025-02-05T07:08:30.350+0000] {subprocess.py:93} INFO - [0m07:08:30    retry_all: False
[2025-02-05T07:08:30.355+0000] {subprocess.py:93} INFO - [0m07:08:30    insecure_mode: False
[2025-02-05T07:08:30.357+0000] {subprocess.py:93} INFO - [0m07:08:30    reuse_connections: None
[2025-02-05T07:08:30.362+0000] {subprocess.py:93} INFO - [0m07:08:30  Registered adapter: snowflake=1.8.4
[2025-02-05T07:08:34.255+0000] {subprocess.py:93} INFO - [0m07:08:34    Connection test: [[32mOK connection ok[0m]
[2025-02-05T07:08:34.257+0000] {subprocess.py:93} INFO - 
[2025-02-05T07:08:34.261+0000] {subprocess.py:93} INFO - [0m07:08:34  [31m1 check failed:[0m
[2025-02-05T07:08:34.265+0000] {subprocess.py:93} INFO - [0m07:08:34  Project loading failed for the following reason:
[2025-02-05T07:08:34.267+0000] {subprocess.py:93} INFO -  project path </tmp/***tmpiz127kmn/dbt_project.yml> not found
[2025-02-05T07:08:34.271+0000] {subprocess.py:93} INFO - 
[2025-02-05T07:08:37.650+0000] {subprocess.py:97} INFO - Command exited with return code 1
[2025-02-05T07:08:37.655+0000] {taskinstance.py:441} INFO - ::group::Post task execution logs
[2025-02-05T07:08:37.714+0000] {taskinstance.py:2905} ERROR - Task failed with exception
Traceback (most recent call last):
  File "/home/airflow/.local/lib/python3.12/site-packages/airflow/models/taskinstance.py", line 465, in _execute_task
    result = _execute_callable(context=context, **execute_callable_kwargs)
             ^^^^^^^^^^^^^^^^^^^^^^^^^^^^^^^^^^^^^^^^^^^^^^^^^^^^^^^^^^^^^
  File "/home/airflow/.local/lib/python3.12/site-packages/airflow/models/taskinstance.py", line 432, in _execute_callable
    return execute_callable(context=context, **execute_callable_kwargs)
           ^^^^^^^^^^^^^^^^^^^^^^^^^^^^^^^^^^^^^^^^^^^^^^^^^^^^^^^^^^^^
  File "/home/airflow/.local/lib/python3.12/site-packages/airflow/models/baseoperator.py", line 401, in wrapper
    return func(self, *args, **kwargs)
           ^^^^^^^^^^^^^^^^^^^^^^^^^^^
  File "/home/airflow/.local/lib/python3.12/site-packages/airflow/operators/bash.py", line 243, in execute
    raise AirflowException(
airflow.exceptions.AirflowException: Bash command failed. The command returned a non-zero exit code 1.
[2025-02-05T07:08:37.746+0000] {taskinstance.py:1206} INFO - Marking task as FAILED. dag_id=dbt_bash_dag_okok, task_id=dbt_debug, run_id=manual__2025-02-05T07:07:51.829582+00:00, execution_date=20250205T070751, start_date=20250205T070759, end_date=20250205T070837
[2025-02-05T07:08:37.823+0000] {standard_task_runner.py:110} ERROR - Failed to execute job 43 for task dbt_debug (Bash command failed. The command returned a non-zero exit code 1.; 268)
[2025-02-05T07:08:37.902+0000] {local_task_job_runner.py:243} INFO - Task exited with return code 1
[2025-02-05T07:08:38.080+0000] {taskinstance.py:3503} INFO - 0 downstream tasks scheduled from follow-on schedule check
[2025-02-05T07:08:38.101+0000] {local_task_job_runner.py:222} INFO - ::endgroup::
