[2025-02-03T09:50:13.733+0000] {local_task_job_runner.py:120} INFO - ::group::Pre task execution logs
[2025-02-03T09:50:13.896+0000] {taskinstance.py:2076} INFO - Dependencies all met for dep_context=non-requeueable deps ti=<TaskInstance: dbt_bash_dag_okok.dbt_debug manual__2025-02-03T09:49:56.231102+00:00 [queued]>
[2025-02-03T09:50:13.995+0000] {taskinstance.py:2076} INFO - Dependencies all met for dep_context=requeueable deps ti=<TaskInstance: dbt_bash_dag_okok.dbt_debug manual__2025-02-03T09:49:56.231102+00:00 [queued]>
[2025-02-03T09:50:14.010+0000] {taskinstance.py:2306} INFO - Starting attempt 1 of 1
[2025-02-03T09:50:14.246+0000] {taskinstance.py:2330} INFO - Executing <Task(BashOperator): dbt_debug> on 2025-02-03 09:49:56.231102+00:00
[2025-02-03T09:50:14.307+0000] {warnings.py:112} WARNING - /home/***/.local/lib/python3.12/site-packages/***/task/task_runner/standard_task_runner.py:62: DeprecationWarning: This process (pid=816) is multi-threaded, use of fork() may lead to deadlocks in the child.
  pid = os.fork()

[2025-02-03T09:50:14.355+0000] {standard_task_runner.py:64} INFO - Started process 817 to run task
[2025-02-03T09:50:14.345+0000] {standard_task_runner.py:90} INFO - Running: ['***', 'tasks', 'run', 'dbt_bash_dag_okok', 'dbt_debug', 'manual__2025-02-03T09:49:56.231102+00:00', '--job-id', '33', '--raw', '--subdir', 'DAGS_FOLDER/test_dbt_2.py', '--cfg-path', '/tmp/tmpgzr4e68t']
[2025-02-03T09:50:14.396+0000] {standard_task_runner.py:91} INFO - Job 33: Subtask dbt_debug
[2025-02-03T09:50:15.112+0000] {task_command.py:426} INFO - Running <TaskInstance: dbt_bash_dag_okok.dbt_debug manual__2025-02-03T09:49:56.231102+00:00 [running]> on host 5d6ad77c43c0
[2025-02-03T09:50:16.675+0000] {taskinstance.py:2648} INFO - Exporting env vars: AIRFLOW_CTX_DAG_OWNER='***' AIRFLOW_CTX_DAG_ID='dbt_bash_dag_okok' AIRFLOW_CTX_TASK_ID='dbt_debug' AIRFLOW_CTX_EXECUTION_DATE='2025-02-03T09:49:56.231102+00:00' AIRFLOW_CTX_TRY_NUMBER='1' AIRFLOW_CTX_DAG_RUN_ID='manual__2025-02-03T09:49:56.231102+00:00'
[2025-02-03T09:50:16.703+0000] {taskinstance.py:430} INFO - ::endgroup::
[2025-02-03T09:50:17.063+0000] {subprocess.py:63} INFO - Tmp dir root location: /tmp
[2025-02-03T09:50:17.072+0000] {subprocess.py:75} INFO - Running command: ['/usr/bin/bash', '-c', 'dbt debug --profiles-dir /opt/***/dbt_projects/project_1']
[2025-02-03T09:50:17.138+0000] {subprocess.py:86} INFO - Output:
[2025-02-03T09:50:41.994+0000] {subprocess.py:93} INFO - [0m09:50:41  Running with dbt=1.8.8
[2025-02-03T09:50:42.436+0000] {subprocess.py:93} INFO - [0m09:50:42  dbt version: 1.8.8
[2025-02-03T09:50:42.439+0000] {subprocess.py:93} INFO - [0m09:50:42  python version: 3.12.4
[2025-02-03T09:50:42.442+0000] {subprocess.py:93} INFO - [0m09:50:42  python path: /home/***/.local/bin/python
[2025-02-03T09:50:42.446+0000] {subprocess.py:93} INFO - [0m09:50:42  os info: Linux-5.15.167.4-microsoft-standard-WSL2-x86_64-with-glibc2.36
[2025-02-03T09:51:05.356+0000] {subprocess.py:93} INFO - [0m09:51:05  Using profiles dir at /opt/***/dbt_projects/project_1
[2025-02-03T09:51:05.387+0000] {subprocess.py:93} INFO - [0m09:51:05  Using profiles.yml file at /opt/***/dbt_projects/project_1/profiles.yml
[2025-02-03T09:51:05.411+0000] {subprocess.py:93} INFO - [0m09:51:05  Using dbt_project.yml file at /tmp/***tmpulxrencw/dbt_project.yml
[2025-02-03T09:51:05.437+0000] {subprocess.py:93} INFO - [0m09:51:05  adapter type: snowflake
[2025-02-03T09:51:05.451+0000] {subprocess.py:93} INFO - [0m09:51:05  adapter version: 1.8.4
[2025-02-03T09:51:05.459+0000] {subprocess.py:93} INFO - [0m09:51:05  Configuration:
[2025-02-03T09:51:05.503+0000] {subprocess.py:93} INFO - [0m09:51:05    profiles.yml file [[32mOK found and valid[0m]
[2025-02-03T09:51:05.512+0000] {subprocess.py:93} INFO - [0m09:51:05    dbt_project.yml file [[31mERROR not found[0m]
[2025-02-03T09:51:05.519+0000] {subprocess.py:93} INFO - [0m09:51:05  Required dependencies:
[2025-02-03T09:51:05.549+0000] {subprocess.py:93} INFO - [0m09:51:05   - git [[32mOK found[0m]
[2025-02-03T09:51:05.552+0000] {subprocess.py:93} INFO - 
[2025-02-03T09:51:05.566+0000] {subprocess.py:93} INFO - [0m09:51:05  Connection:
[2025-02-03T09:51:05.569+0000] {subprocess.py:93} INFO - [0m09:51:05    account: nmbqhvk-ns46391
[2025-02-03T09:51:05.571+0000] {subprocess.py:93} INFO - [0m09:51:05    user: TUAN_123
[2025-02-03T09:51:05.575+0000] {subprocess.py:93} INFO - [0m09:51:05    database: DBT_TEST
[2025-02-03T09:51:05.584+0000] {subprocess.py:93} INFO - [0m09:51:05    warehouse: MY_WAREHOUSE
[2025-02-03T09:51:05.586+0000] {subprocess.py:93} INFO - [0m09:51:05    role: MY_ROLE
[2025-02-03T09:51:05.588+0000] {subprocess.py:93} INFO - [0m09:51:05    schema: MAIN
[2025-02-03T09:51:05.602+0000] {subprocess.py:93} INFO - [0m09:51:05    authenticator: None
[2025-02-03T09:51:05.605+0000] {subprocess.py:93} INFO - [0m09:51:05    oauth_client_id: None
[2025-02-03T09:51:05.607+0000] {subprocess.py:93} INFO - [0m09:51:05    query_tag: None
[2025-02-03T09:51:05.610+0000] {subprocess.py:93} INFO - [0m09:51:05    client_session_keep_alive: False
[2025-02-03T09:51:05.633+0000] {subprocess.py:93} INFO - [0m09:51:05    host: None
[2025-02-03T09:51:05.638+0000] {subprocess.py:93} INFO - [0m09:51:05    port: None
[2025-02-03T09:51:05.640+0000] {subprocess.py:93} INFO - [0m09:51:05    proxy_host: None
[2025-02-03T09:51:05.656+0000] {subprocess.py:93} INFO - [0m09:51:05    proxy_port: None
[2025-02-03T09:51:05.668+0000] {subprocess.py:93} INFO - [0m09:51:05    protocol: None
[2025-02-03T09:51:05.674+0000] {subprocess.py:93} INFO - [0m09:51:05    connect_retries: 1
[2025-02-03T09:51:05.686+0000] {subprocess.py:93} INFO - [0m09:51:05    connect_timeout: None
[2025-02-03T09:51:05.690+0000] {subprocess.py:93} INFO - [0m09:51:05    retry_on_database_errors: False
[2025-02-03T09:51:05.705+0000] {subprocess.py:93} INFO - [0m09:51:05    retry_all: False
[2025-02-03T09:51:05.723+0000] {subprocess.py:93} INFO - [0m09:51:05    insecure_mode: False
[2025-02-03T09:51:05.726+0000] {subprocess.py:93} INFO - [0m09:51:05    reuse_connections: None
[2025-02-03T09:51:05.728+0000] {subprocess.py:93} INFO - [0m09:51:05  Registered adapter: snowflake=1.8.4
[2025-02-03T09:51:17.434+0000] {subprocess.py:93} INFO - [0m09:51:17    Connection test: [[32mOK connection ok[0m]
[2025-02-03T09:51:17.448+0000] {subprocess.py:93} INFO - 
[2025-02-03T09:51:17.454+0000] {subprocess.py:93} INFO - [0m09:51:17  [31m1 check failed:[0m
[2025-02-03T09:51:17.471+0000] {subprocess.py:93} INFO - [0m09:51:17  Project loading failed for the following reason:
[2025-02-03T09:51:17.485+0000] {subprocess.py:93} INFO -  project path </tmp/***tmpulxrencw/dbt_project.yml> not found
[2025-02-03T09:51:17.506+0000] {subprocess.py:93} INFO - 
[2025-02-03T09:51:20.984+0000] {subprocess.py:97} INFO - Command exited with return code 1
[2025-02-03T09:51:21.001+0000] {taskinstance.py:441} INFO - ::group::Post task execution logs
[2025-02-03T09:51:21.073+0000] {taskinstance.py:2905} ERROR - Task failed with exception
Traceback (most recent call last):
  File "/home/airflow/.local/lib/python3.12/site-packages/airflow/models/taskinstance.py", line 465, in _execute_task
    result = _execute_callable(context=context, **execute_callable_kwargs)
             ^^^^^^^^^^^^^^^^^^^^^^^^^^^^^^^^^^^^^^^^^^^^^^^^^^^^^^^^^^^^^
  File "/home/airflow/.local/lib/python3.12/site-packages/airflow/models/taskinstance.py", line 432, in _execute_callable
    return execute_callable(context=context, **execute_callable_kwargs)
           ^^^^^^^^^^^^^^^^^^^^^^^^^^^^^^^^^^^^^^^^^^^^^^^^^^^^^^^^^^^^
  File "/home/airflow/.local/lib/python3.12/site-packages/airflow/models/baseoperator.py", line 401, in wrapper
    return func(self, *args, **kwargs)
           ^^^^^^^^^^^^^^^^^^^^^^^^^^^
  File "/home/airflow/.local/lib/python3.12/site-packages/airflow/operators/bash.py", line 243, in execute
    raise AirflowException(
airflow.exceptions.AirflowException: Bash command failed. The command returned a non-zero exit code 1.
[2025-02-03T09:51:21.109+0000] {taskinstance.py:1206} INFO - Marking task as FAILED. dag_id=dbt_bash_dag_okok, task_id=dbt_debug, run_id=manual__2025-02-03T09:49:56.231102+00:00, execution_date=20250203T094956, start_date=20250203T095013, end_date=20250203T095121
[2025-02-03T09:51:21.205+0000] {standard_task_runner.py:110} ERROR - Failed to execute job 33 for task dbt_debug (Bash command failed. The command returned a non-zero exit code 1.; 817)
[2025-02-03T09:51:21.274+0000] {local_task_job_runner.py:243} INFO - Task exited with return code 1
[2025-02-03T09:51:21.449+0000] {taskinstance.py:3503} INFO - 0 downstream tasks scheduled from follow-on schedule check
[2025-02-03T09:51:21.468+0000] {local_task_job_runner.py:222} INFO - ::endgroup::
